{
 "cells": [
  {
   "cell_type": "code",
   "execution_count": 7,
   "metadata": {},
   "outputs": [],
   "source": [
    "import os\n",
    "import json\n",
    "import traceback\n",
    "import pandas as pd"
   ]
  },
  {
   "cell_type": "code",
   "execution_count": 8,
   "metadata": {},
   "outputs": [],
   "source": [
    "from langchain.chat_models import ChatOpenAI\n",
    "from langchain import OpenAI"
   ]
  },
  {
   "cell_type": "code",
   "execution_count": 9,
   "metadata": {},
   "outputs": [
    {
     "data": {
      "text/plain": [
       "True"
      ]
     },
     "execution_count": 9,
     "metadata": {},
     "output_type": "execute_result"
    }
   ],
   "source": [
    "from dotenv import load_dotenv\n",
    "\n",
    "load_dotenv()  # take environment variables from .env."
   ]
  },
  {
   "cell_type": "code",
   "execution_count": 10,
   "metadata": {},
   "outputs": [],
   "source": [
    "openai_api_key = os.getenv(\"OPENAI_API_KEY\")"
   ]
  },
  {
   "cell_type": "code",
   "execution_count": 11,
   "metadata": {},
   "outputs": [
    {
     "name": "stdout",
     "output_type": "stream",
     "text": [
      "API Key Loaded: sk-proj-dClZEg2Wohr5WsYwtGwuT3BlbkFJNwGnCyySSDR5hzdJ65dJ\n"
     ]
    }
   ],
   "source": [
    "print(f\"API Key Loaded: {openai_api_key}\")"
   ]
  },
  {
   "cell_type": "code",
   "execution_count": 12,
   "metadata": {},
   "outputs": [
    {
     "ename": "ImportError",
     "evalue": "Could not import openai python package. Please install it with `pip install openai`.",
     "output_type": "error",
     "traceback": [
      "\u001b[1;31m---------------------------------------------------------------------------\u001b[0m",
      "\u001b[1;31mModuleNotFoundError\u001b[0m                       Traceback (most recent call last)",
      "File \u001b[1;32mc:\\Users\\banda\\AppData\\Local\\Programs\\Python\\Python39\\lib\\site-packages\\langchain_community\\chat_models\\openai.py:305\u001b[0m, in \u001b[0;36mChatOpenAI.validate_environment\u001b[1;34m(cls, values)\u001b[0m\n\u001b[0;32m    304\u001b[0m \u001b[38;5;28;01mtry\u001b[39;00m:\n\u001b[1;32m--> 305\u001b[0m     \u001b[38;5;28;01mimport\u001b[39;00m \u001b[38;5;21;01mopenai\u001b[39;00m\n\u001b[0;32m    307\u001b[0m \u001b[38;5;28;01mexcept\u001b[39;00m \u001b[38;5;167;01mImportError\u001b[39;00m:\n",
      "\u001b[1;31mModuleNotFoundError\u001b[0m: No module named 'openai'",
      "\nDuring handling of the above exception, another exception occurred:\n",
      "\u001b[1;31mImportError\u001b[0m                               Traceback (most recent call last)",
      "Cell \u001b[1;32mIn[12], line 1\u001b[0m\n\u001b[1;32m----> 1\u001b[0m llm \u001b[38;5;241m=\u001b[39m \u001b[43mChatOpenAI\u001b[49m\u001b[43m(\u001b[49m\u001b[43mopenai_api_key\u001b[49m\u001b[38;5;241;43m=\u001b[39;49m\u001b[43mopenai_api_key\u001b[49m\u001b[43m,\u001b[49m\u001b[43m \u001b[49m\u001b[43mmodel_name\u001b[49m\u001b[38;5;241;43m=\u001b[39;49m\u001b[38;5;124;43m\"\u001b[39;49m\u001b[38;5;124;43mgpt-3.5-turbo\u001b[39;49m\u001b[38;5;124;43m\"\u001b[39;49m\u001b[43m,\u001b[49m\u001b[43m \u001b[49m\u001b[43mtemperature\u001b[49m\u001b[38;5;241;43m=\u001b[39;49m\u001b[38;5;241;43m0.5\u001b[39;49m\u001b[43m)\u001b[49m\n",
      "File \u001b[1;32mc:\\Users\\banda\\AppData\\Local\\Programs\\Python\\Python39\\lib\\site-packages\\langchain_core\\_api\\deprecation.py:203\u001b[0m, in \u001b[0;36mdeprecated.<locals>.deprecate.<locals>.finalize.<locals>.warn_if_direct_instance\u001b[1;34m(self, *args, **kwargs)\u001b[0m\n\u001b[0;32m    201\u001b[0m     warned \u001b[38;5;241m=\u001b[39m \u001b[38;5;28;01mTrue\u001b[39;00m\n\u001b[0;32m    202\u001b[0m     emit_warning()\n\u001b[1;32m--> 203\u001b[0m \u001b[38;5;28;01mreturn\u001b[39;00m wrapped(\u001b[38;5;28mself\u001b[39m, \u001b[38;5;241m*\u001b[39margs, \u001b[38;5;241m*\u001b[39m\u001b[38;5;241m*\u001b[39mkwargs)\n",
      "File \u001b[1;32mc:\\Users\\banda\\AppData\\Local\\Programs\\Python\\Python39\\lib\\site-packages\\pydantic\\v1\\main.py:339\u001b[0m, in \u001b[0;36mBaseModel.__init__\u001b[1;34m(__pydantic_self__, **data)\u001b[0m\n\u001b[0;32m    333\u001b[0m \u001b[38;5;250m\u001b[39m\u001b[38;5;124;03m\"\"\"\u001b[39;00m\n\u001b[0;32m    334\u001b[0m \u001b[38;5;124;03mCreate a new model by parsing and validating input data from keyword arguments.\u001b[39;00m\n\u001b[0;32m    335\u001b[0m \n\u001b[0;32m    336\u001b[0m \u001b[38;5;124;03mRaises ValidationError if the input data cannot be parsed to form a valid model.\u001b[39;00m\n\u001b[0;32m    337\u001b[0m \u001b[38;5;124;03m\"\"\"\u001b[39;00m\n\u001b[0;32m    338\u001b[0m \u001b[38;5;66;03m# Uses something other than `self` the first arg to allow \"self\" as a settable attribute\u001b[39;00m\n\u001b[1;32m--> 339\u001b[0m values, fields_set, validation_error \u001b[38;5;241m=\u001b[39m \u001b[43mvalidate_model\u001b[49m\u001b[43m(\u001b[49m\u001b[43m__pydantic_self__\u001b[49m\u001b[38;5;241;43m.\u001b[39;49m\u001b[38;5;18;43m__class__\u001b[39;49m\u001b[43m,\u001b[49m\u001b[43m \u001b[49m\u001b[43mdata\u001b[49m\u001b[43m)\u001b[49m\n\u001b[0;32m    340\u001b[0m \u001b[38;5;28;01mif\u001b[39;00m validation_error:\n\u001b[0;32m    341\u001b[0m     \u001b[38;5;28;01mraise\u001b[39;00m validation_error\n",
      "File \u001b[1;32mc:\\Users\\banda\\AppData\\Local\\Programs\\Python\\Python39\\lib\\site-packages\\pydantic\\v1\\main.py:1048\u001b[0m, in \u001b[0;36mvalidate_model\u001b[1;34m(model, input_data, cls)\u001b[0m\n\u001b[0;32m   1046\u001b[0m \u001b[38;5;28;01mfor\u001b[39;00m validator \u001b[38;5;129;01min\u001b[39;00m model\u001b[38;5;241m.\u001b[39m__pre_root_validators__:\n\u001b[0;32m   1047\u001b[0m     \u001b[38;5;28;01mtry\u001b[39;00m:\n\u001b[1;32m-> 1048\u001b[0m         input_data \u001b[38;5;241m=\u001b[39m \u001b[43mvalidator\u001b[49m\u001b[43m(\u001b[49m\u001b[43mcls_\u001b[49m\u001b[43m,\u001b[49m\u001b[43m \u001b[49m\u001b[43minput_data\u001b[49m\u001b[43m)\u001b[49m\n\u001b[0;32m   1049\u001b[0m     \u001b[38;5;28;01mexcept\u001b[39;00m (\u001b[38;5;167;01mValueError\u001b[39;00m, \u001b[38;5;167;01mTypeError\u001b[39;00m, \u001b[38;5;167;01mAssertionError\u001b[39;00m) \u001b[38;5;28;01mas\u001b[39;00m exc:\n\u001b[0;32m   1050\u001b[0m         \u001b[38;5;28;01mreturn\u001b[39;00m {}, \u001b[38;5;28mset\u001b[39m(), ValidationError([ErrorWrapper(exc, loc\u001b[38;5;241m=\u001b[39mROOT_KEY)], cls_)\n",
      "File \u001b[1;32mc:\\Users\\banda\\AppData\\Local\\Programs\\Python\\Python39\\lib\\site-packages\\langchain_core\\utils\\pydantic.py:149\u001b[0m, in \u001b[0;36mpre_init.<locals>.wrapper\u001b[1;34m(cls, values)\u001b[0m\n\u001b[0;32m    146\u001b[0m                 values[name] \u001b[38;5;241m=\u001b[39m field_info\u001b[38;5;241m.\u001b[39mdefault\n\u001b[0;32m    148\u001b[0m \u001b[38;5;66;03m# Call the decorated function\u001b[39;00m\n\u001b[1;32m--> 149\u001b[0m \u001b[38;5;28;01mreturn\u001b[39;00m \u001b[43mfunc\u001b[49m\u001b[43m(\u001b[49m\u001b[38;5;28;43mcls\u001b[39;49m\u001b[43m,\u001b[49m\u001b[43m \u001b[49m\u001b[43mvalues\u001b[49m\u001b[43m)\u001b[49m\n",
      "File \u001b[1;32mc:\\Users\\banda\\AppData\\Local\\Programs\\Python\\Python39\\lib\\site-packages\\langchain_community\\chat_models\\openai.py:308\u001b[0m, in \u001b[0;36mChatOpenAI.validate_environment\u001b[1;34m(cls, values)\u001b[0m\n\u001b[0;32m    305\u001b[0m     \u001b[38;5;28;01mimport\u001b[39;00m \u001b[38;5;21;01mopenai\u001b[39;00m\n\u001b[0;32m    307\u001b[0m \u001b[38;5;28;01mexcept\u001b[39;00m \u001b[38;5;167;01mImportError\u001b[39;00m:\n\u001b[1;32m--> 308\u001b[0m     \u001b[38;5;28;01mraise\u001b[39;00m \u001b[38;5;167;01mImportError\u001b[39;00m(\n\u001b[0;32m    309\u001b[0m         \u001b[38;5;124m\"\u001b[39m\u001b[38;5;124mCould not import openai python package. \u001b[39m\u001b[38;5;124m\"\u001b[39m\n\u001b[0;32m    310\u001b[0m         \u001b[38;5;124m\"\u001b[39m\u001b[38;5;124mPlease install it with `pip install openai`.\u001b[39m\u001b[38;5;124m\"\u001b[39m\n\u001b[0;32m    311\u001b[0m     )\n\u001b[0;32m    313\u001b[0m \u001b[38;5;28;01mif\u001b[39;00m is_openai_v1():\n\u001b[0;32m    314\u001b[0m     client_params \u001b[38;5;241m=\u001b[39m {\n\u001b[0;32m    315\u001b[0m         \u001b[38;5;124m\"\u001b[39m\u001b[38;5;124mapi_key\u001b[39m\u001b[38;5;124m\"\u001b[39m: values[\u001b[38;5;124m\"\u001b[39m\u001b[38;5;124mopenai_api_key\u001b[39m\u001b[38;5;124m\"\u001b[39m],\n\u001b[0;32m    316\u001b[0m         \u001b[38;5;124m\"\u001b[39m\u001b[38;5;124morganization\u001b[39m\u001b[38;5;124m\"\u001b[39m: values[\u001b[38;5;124m\"\u001b[39m\u001b[38;5;124mopenai_organization\u001b[39m\u001b[38;5;124m\"\u001b[39m],\n\u001b[1;32m   (...)\u001b[0m\n\u001b[0;32m    322\u001b[0m         \u001b[38;5;124m\"\u001b[39m\u001b[38;5;124mhttp_client\u001b[39m\u001b[38;5;124m\"\u001b[39m: values[\u001b[38;5;124m\"\u001b[39m\u001b[38;5;124mhttp_client\u001b[39m\u001b[38;5;124m\"\u001b[39m],\n\u001b[0;32m    323\u001b[0m     }\n",
      "\u001b[1;31mImportError\u001b[0m: Could not import openai python package. Please install it with `pip install openai`."
     ]
    }
   ],
   "source": [
    "llm = ChatOpenAI(openai_api_key=openai_api_key, model_name=\"gpt-3.5-turbo\", temperature=0.5)"
   ]
  }
 ],
 "metadata": {
  "kernelspec": {
   "display_name": "Python 3",
   "language": "python",
   "name": "python3"
  },
  "language_info": {
   "codemirror_mode": {
    "name": "ipython",
    "version": 3
   },
   "file_extension": ".py",
   "mimetype": "text/x-python",
   "name": "python",
   "nbconvert_exporter": "python",
   "pygments_lexer": "ipython3",
   "version": "3.12.4"
  }
 },
 "nbformat": 4,
 "nbformat_minor": 2
}
